<?xml version="1.0" encoding="utf-8"?>
<robot
  name="hit_mechanism2">
  <link
    name="base_link">
    <inertial>
      <origin
        xyz="4.31443873266484E-06 -0.0112543220516447 1.77018723506589E-05"
        rpy="0 0 0" />
      <mass
        value="0.000625677275979962" />
      <inertia
        ixx="2.66681205666472E-08"
        ixy="1.47605336302959E-11"
        ixz="-8.0812306001521E-12"
        iyy="2.83505957294567E-09"
        iyz="6.05615465514296E-11"
        izz="2.66369567363667E-08" />
    </inertial>
    <visual>
      <origin
        xyz="0 0 0"
        rpy="0 0 0" />
      <geometry>
        <mesh
          filename="package://hit_mechanism2/meshes/base_link.STL" />
      </geometry>
      <material
        name="">
        <color
          rgba="1 1 1 1" />
      </material>
    </visual>
    <collision>
      <origin
        xyz="0 0 0"
        rpy="0 0 0" />
      <geometry>
        <mesh
          filename="package://hit_mechanism2/meshes/base_link.STL" />
      </geometry>
    </collision>
  </link>
  <link
    name="cam_link">
    <inertial>
      <origin
        xyz="0.0220683296994079 -0.01543200493308 0.00500001031926959"
        rpy="0 0 0" />
      <mass
        value="0.123418384619757" />
      <inertia
        ixx="0.000148837961754261"
        ixy="-2.7280875896284E-05"
        ixz="1.49584095373529E-10"
        iyy="0.000114327597188868"
        iyz="-1.00908585696353E-10"
        izz="0.00026110865331133" />
    </inertial>
    <visual>
      <origin
        xyz="0 0 0"
        rpy="0 0 0" />
      <geometry>
        <mesh
          filename="package://hit_mechanism2/meshes/cam_link.STL" />
      </geometry>
      <material
        name="">
        <color
          rgba="1 1 1 1" />
      </material>
    </visual>
    <collision>
      <origin
        xyz="0 0 0"
        rpy="0 0 0" />
      <geometry>
        <mesh
          filename="package://hit_mechanism2/meshes/cam_link.STL" />
      </geometry>
    </collision>
  </link>
  <joint
    name="joint1"
    type="continuous">
    <origin
      xyz="0 0 0"
      rpy="1.5708 0 0" />
    <parent
      link="base_link" />
    <child
      link="cam_link" />
    <axis
      xyz="0 0 1" />
  </joint>
  <link
    name="link1">
    <inertial>
      <origin
        xyz="0.00299163531431289 0.0796750101476338 0.00500000000000001"
        rpy="0 0 0" />
      <mass
        value="0.0157169361063451" />
      <inertia
        ixx="3.2547397545957E-05"
        ixy="1.26517185297356E-21"
        ixz="-1.33294318437382E-23"
        iyy="2.62779971864936E-07"
        iyz="-1.76319824412546E-22"
        izz="3.25482285827161E-05" />
    </inertial>
    <visual>
      <origin
        xyz="0 0 0"
        rpy="0 0 0" />
      <geometry>
        <mesh
          filename="package://hit_mechanism2/meshes/link1.STL" />
      </geometry>
      <material
        name="">
        <color
          rgba="1 1 1 1" />
      </material>
    </visual>
    <collision>
      <origin
        xyz="0 0 0"
        rpy="0 0 0" />
      <geometry>
        <mesh
          filename="package://hit_mechanism2/meshes/link1.STL" />
      </geometry>
    </collision>
  </link>
  <joint
    name="joint2"
    type="prismatic">
    <origin
      xyz="-0.0130168913709829 0.00999999999999955 0.0350812000102613"
      rpy="1.5707963267949 0 0" />
    <parent
      link="base_link" />
    <child
      link="link1" />
    <axis
      xyz="0 1 0" />
    <limit
      lower="25"
      upper="55"
      effort="0"
      velocity="0" />
  </joint>
  <link
    name="link2">
    <inertial>
      <origin
        xyz="2.51534904016637E-17 0.00121248005426174 0.00499999999999999"
        rpy="0 0 0" />
      <mass
        value="0.00285884931476671" />
      <inertia
        ixx="1.01727388117116E-07"
        ixy="-9.71844339164884E-42"
        ixz="-2.05315675656235E-39"
        iyy="1.01727388117116E-07"
        iyz="-3.30871004211729E-40"
        izz="1.55807287654786E-07" />
    </inertial>
    <visual>
      <origin
        xyz="0 0 0"
        rpy="0 0 0" />
      <geometry>
        <mesh
          filename="package://hit_mechanism2/meshes/link2.STL" />
      </geometry>
      <material
        name="">
        <color
          rgba="1 1 1 1" />
      </material>
    </visual>
    <collision>
      <origin
        xyz="0 0 0"
        rpy="0 0 0" />
      <geometry>
        <mesh
          filename="package://hit_mechanism2/meshes/link2.STL" />
      </geometry>
    </collision>
  </link>
  <joint
    name="joint3"
    type="continuous">
    <origin
      xyz="0.00299163531431282 0.00299170343325255 0.01"
      rpy="0 0 0" />
    <parent
      link="link1" />
    <child
      link="link2" />
    <axis
      xyz="0 0 1" />
  </joint>
</robot>