<?xml version="1.0" encoding="utf-8"?>
<!-- This URDF was automatically created by SolidWorks to URDF Exporter! Originally created by Stephen Brawner (brawner@gmail.com) 
     Commit Version: 1.6.0-4-g7f85cfe  Build Version: 1.6.7995.38578
     For more information, please see http://wiki.ros.org/sw_urdf_exporter -->
<robot
  name="cam.SLDASM">
  <link
    name="base_link">
    <inertial>
      <origin
        xyz="0.00516771533428161 -0.14768022954333 0.0192011585485057"
        rpy="0 0 0" />
      <mass
        value="0.000625677275979962" />
      <inertia
        ixx="2.66695147124345E-08"
        ixy="-4.46270353436079E-12"
        ixz="-7.98052308845236E-12"
        iyy="2.66355625905794E-08"
        iyz="-6.18214002186702E-11"
        izz="2.83505957294567E-09" />
    </inertial>
    <visual>
      <origin
        xyz="0 0 0"
        rpy="0 0 0" />
      <geometry>
        <mesh
          filename="package://cam.SLDASM/meshes/base_link.STL" />
      </geometry>
      <material
        name="">
        <color
          rgba="1 1 1 1" />
      </material>
    </visual>
    <collision>
      <origin
        xyz="0 0 0"
        rpy="0 0 0" />
      <geometry>
        <mesh
          filename="package://cam.SLDASM/meshes/base_link.STL" />
      </geometry>
    </collision>
  </link>
  <link
    name="cam_link">
    <inertial>
      <origin
        xyz="-0.00356715717082566 -0.0284751150841584 0.00499971930811462"
        rpy="0 0 0" />
      <mass
        value="0.0932420859273589" />
      <inertia
        ixx="5.44448424617422E-05"
        ixy="1.9417859569232E-06"
        ixz="1.13490266794473E-10"
        iyy="9.84612983282398E-05"
        iyz="-2.23481033347778E-11"
        izz="0.0001513520083394" />
    </inertial>
    <visual>
      <origin
        xyz="0 0 0"
        rpy="0 0 0" />
      <geometry>
        <mesh
          filename="package://cam.SLDASM/meshes/cam_link.STL" />
      </geometry>
      <material
        name="">
        <color
          rgba="1 1 1 1" />
      </material>
    </visual>
    <collision>
      <origin
        xyz="0 0 0"
        rpy="0 0 0" />
      <geometry>
        <mesh
          filename="package://cam.SLDASM/meshes/cam_link.STL" />
      </geometry>
    </collision>
  </link>
  <joint
    name="joint1"
    type="continuous">
    <origin
      xyz="0.0051654 -0.0081691 -0.1477"
      rpy="1.5708 0.0054199 0" />
    <parent
      link="base_link" />
    <child
      link="cam_link" />
    <axis
      xyz="0 0 1" />
  </joint>
  <link
    name="link2">
    <inertial>
      <origin
        xyz="0.0029916353143129 -0.0786105751020638 0.005"
        rpy="0 0 0" />
      <mass
        value="0.0157169361063451" />
      <inertia
        ixx="3.2547397545957E-05"
        ixy="1.22788339509305E-21"
        ixz="-1.07819767184313E-23"
        iyy="2.62779971864936E-07"
        iyz="-3.95782292676014E-22"
        izz="3.25482285827161E-05" />
    </inertial>
    <visual>
      <origin
        xyz="0 0 0"
        rpy="0 0 0" />
      <geometry>
        <mesh
          filename="package://cam.SLDASM/meshes/link2.STL" />
      </geometry>
      <material
        name="">
        <color
          rgba="1 1 1 1" />
      </material>
    </visual>
    <collision>
      <origin
        xyz="0 0 0"
        rpy="0 0 0" />
      <geometry>
        <mesh
          filename="package://cam.SLDASM/meshes/link2.STL" />
      </geometry>
    </collision>
  </link>
  <joint
    name="joint2"
    type="prismatic">
    <origin
      xyz="-0.0078263 0.0018309 0.049232"
      rpy="1.5708 0 0" />
    <parent
      link="base_link" />
    <child
      link="link2" />
    <axis
      xyz="0 1 0" />
    <limit
      lower="0"
      upper="0"
      effort="0"
      velocity="0" />
  </joint>
  <link
    name="link3">
    <inertial>
      <origin
        xyz="1.22298005056365E-16 -1.2490009027033E-16 0.005"
        rpy="0 0 0" />
      <mass
        value="0.0149225651045515" />
      <inertia
        ixx="1.96356085834057E-06"
        ixy="7.94093388050907E-23"
        ixz="8.52679742638038E-22"
        iyy="1.96356085834057E-06"
        iyz="-6.31086664618679E-21"
        izz="3.67841229827195E-06" />
    </inertial>
    <visual>
      <origin
        xyz="0 0 0"
        rpy="0 0 0" />
      <geometry>
        <mesh
          filename="package://cam.SLDASM/meshes/link3.STL" />
      </geometry>
      <material
        name="">
        <color
          rgba="1 1 1 1" />
      </material>
    </visual>
    <collision>
      <origin
        xyz="0 0 0"
        rpy="0 0 0" />
      <geometry>
        <mesh
          filename="package://cam.SLDASM/meshes/link3.STL" />
      </geometry>
    </collision>
  </link>
  <joint
    name="joint3"
    type="continuous">
    <origin
      xyz="0.0029916 -0.15408 0.01"
      rpy="0 0 -0.12045" />
    <parent
      link="link2" />
    <child
      link="link3" />
    <axis
      xyz="0 0 1" />
  </joint>
  <link
    name="link4">
    <inertial>
      <origin
        xyz="0.00592225665564003 0.000450945063349195 0.00495182852239552"
        rpy="0 0 0" />
      <mass
        value="0.00468304605147202" />
      <inertia
        ixx="2.21532278505678E-07"
        ixy="-1.02213626415837E-23"
        ixz="-2.08051185398901E-10"
        iyy="5.52920229009265E-07"
        iyz="5.03242766367641E-22"
        izz="4.09438718028121E-07" />
    </inertial>
    <visual>
      <origin
        xyz="0 0 0"
        rpy="0 0 0" />
      <geometry>
        <mesh
          filename="package://cam.SLDASM/meshes/link4.STL" />
      </geometry>
      <material
        name="">
        <color
          rgba="1 1 1 1" />
      </material>
    </visual>
    <collision>
      <origin
        xyz="0 0 0"
        rpy="0 0 0" />
      <geometry>
        <mesh
          filename="package://cam.SLDASM/meshes/link4.STL" />
      </geometry>
    </collision>
  </link>
  <joint
    name="joint4"
    type="fixed">
    <origin
      xyz="-0.0098346 0.0020564 0.00068033"
      rpy="1.5708 0 0" />
    <parent
      link="base_link" />
    <child
      link="link4" />
    <axis
      xyz="0 0 0" />
  </joint>
</robot>